Workbook

Sheet #.專案通訊錄
A1: 類別 | B1: 單位簡稱 | C1: 姓名/職稱 | D1: LINE名稱 | E1: 聯絡手機 | F1: 辦公室電話 | G1: 聯絡信箱 | H1: 專案雲端路徑 | I1: 工程名稱 | J1: 欄1
A2: 承覽單位 | B2: 乾坤測繪 | C2: 計畫督導 洪慶忠 | E2: 0933587955 | F2: 04-24722488 | G2: p66984100@gmail.com
A3: 承覽單位 | B3: 乾坤測繪 | C3: 主持人 王駿穠 | D3: jujuiacc | E3: 0922256013 | F3: 04-24722488 | G3: ck.estimate666@gmail.com
A4: 承覽單位 | B4: 乾坤測繪 | C4: 專案PM 李昭德 | G4: ck.estimate666@gmail.com
A5: 查估單位 | B5: 威名估價 | C5: 威名估價師 張志中 | H5: https://reurl.cc/R98q0x
A6: 查估單位 | B6: 全國估價 | C6: 全國估價師 張子亮 | E6: 0911863755 | G6: lander2000y@yahoo.com.tw | H6: https://reurl.cc/ORzM77
A7: 查估單位 | B7: 昇揚估價 | C7: 昇揚估價師 欒中文 | H7: https://reurl.cc/dq9nVV
A8: 查估單位 | B8: 冠誠估價 | C8: 冠誠估價師 劉冠于 | F8: 04-22208181 | G8: goodjobliu99@gmail.com | H8: https://reurl.cc/vKoaqk
A10: 機關承辦 | B10: 桃園工務局 | C10: 工程員 廖偉翔 | F10: 03-3322101#6755 | G10: 10079858@mail.tycg.gov.tw
A11: 案件承辦 | B11: 桃園工務局 | C11: 行政助理 粘亞溱 | F11: (03)332-2101#6755 | G11: 80013503@mail.tycg.gov.tw | H11: https://reurl.cc/EbM8Dm | I11: 桃園市八德區霄裡公園及周邊道路興闢工程 | J11: 115年_派工單號003
A12: 案件承辦 | B12: 桃園工務局 | C12: 行政助理 張語情 | F12: (03)332-2101#6755 | G12: 80043818@mail.tycg.gov.tw | I12: 龍潭區文化路與文化路1011巷道路開闢工程
A13: 案件承辦 | B13: 桃園工務局 | C13: 約催助理 吳佳芸 | F13: (03)332-2101#6755 | G13: 10044694@mail.tycg.gov.tw | H13: https://reurl.cc/rKjOr1 | I13: 中壢區龍岡路4-1-10M計畫道路路口瓶頸打通工程 | J13: 115年_派工單號003

Sheet 1.轄管工程清單
A1: 項次 | B1: 審議年度 | C1: 案件 類型 | D1: 行政區 | E1: 工程名稱 | F1: 工程起點 | G1: 工程迄點 | H1: 道路長度(公尺) | I1: 現況路寬 (公尺) | J1: 計畫路寬 (公尺) | K1: 公有土地 (筆) | L1: 私有土地 (筆) | M1: RC數量 (棟) | N1: 鐵皮屋數量 (棟) | O1: 工程費 (元) | P1: 用地費 (元) | Q1: 補償費 (元) | R1: 總經費 (元) | S1: 審議結果 | T1: 備註 | U1: 完工日期 | V1: 都市計畫 | W1: 提案人 | X1: 承攬案件(115年查估) | Y1: 案件承辦 | Z1: 分案名稱 | AA1: 派工單號 | AB1: 查估單位 | AC1: 機關關聯公文 | AD1: 乾坤關聯公文 | AE1: 附件紀錄
A2: 1 | B2: 106 | C2: 瓶頸 | D2: 桃園區 | E2: 瑞慶路(敬三街至瑞慶路377巷) | H2: 40 | I2: 未開闢 | J2: 10 | K2: 3 | L2: 3 | M2: 0 | N2: 1 | O2: 960000 | P2: 4104542.4 | Q2: 0 | R2: 5064542.4 | S2: 通過
A3: 2 | B3: 106 | C3: 瓶頸 | D3: 桃園區 | E3: 國強二街 | H3: 35 | I3: 未開闢 | J3: 10 | K3: 1 | L3: 6 | M3: 0 | N3: 3 | O3: 1400000 | P3: 20607647 | Q3: 1212000 | R3: 23219647 | S3: 通過 | T3: ※黃婉如 | W3: 黃婉如
A4: 3 | B4: 106 | C4: 瓶頸 | D4: 桃園區 | E4: 民富三街 | H4: 25 | I4: 未開闢 | J4: 8 | K4: 1 | L4: 1 | M4: 0 | N4: 0 | O4: 800000 | P4: 13130964 | Q4: 0 | R4: 13930964 | S4: 通過 | U4: (107.4.23)
A5: 4 | B5: 106 | C5: 瓶頸 | D5: 桃園區 | E5: 同德十二街(中埔七街至永安北路) | H5: 25 | I5: 未開闢 | J5: 10 | K5: 1 | L5: 3 | M5: 0 | N5: 1 | O5: 1000000 | P5: 72327522 | Q5: 3272400 | R5: 76599922 | S5: 通過
A6: 5 | B6: 106 | C6: 瓶頸 | D6: 桃園區 | E6: 慈華街 | H6: 15 | I6: 5~8 | J6: 8 | K6: 2 | L6: 2 | M6: 0 | N6: 0 | O6: 480000 | P6: 40468680 | Q6: 0 | R6: 40948680 | T6: ※黃景熙 | W6: 黃景熙
A7: 6 | B7: 106 | C7: 瓶頸 | D7: 桃園區 | E7: 孝一街 | H7: 34 | I7: 未開闢 | J7: 7 | K7: 2 | L7: 2 | M7: 0 | N7: 0 | O7: 672000 | P7: 18888360 | Q7: 0 | R7: 11410560 | T7: ※黃婉如 | U7: (106.12.29) | W7: 黃婉如
A8: 7 | B8: 106 | C8: 瓶頸 | D8: 中壢區 | E8: 榮安二街 | H8: 20 | I8: 未開闢 | J8: 8 | K8: 0 | L8: 3 | M8: 1 | N8: 0 | O8: 640000 | P8: 6026400 | Q8: 2424000 | R8: 9090400 | S8: 通過
A9: 8 | B9: 106 | C9: 瓶頸 | D9: 中壢區 | E9: 富村街計畫道路 | F9: 富村街 | G9: 榮民路56巷 | H9: 34 | I9: 未開闢 | J9: 8 | K9: 0 | L9: 2 | M9: 2 | N9: 0 | O9: 1088000 | P9: 96645960 | Q9: 0 | R9: 97733960 | S9: 合併處理 (106.5.24) | T9: 經複審後，移計前核定瓶頸道路一併處理者。 | U9: (107.10.30)
A10: 9 | B10: 106 | C10: 瓶頸 | D10: 中壢區 | E10: 新興路228號旁計畫道路 | H10: 45 | I10: 未開闢 | J10: 8 | K10: 0 | L10: 8 | M10: 0 | N10: 2 | O10: 1440000 | P10: 25123550 | Q10: 3030000 | R10: 29593550 | S10: 通過
A11: 10 | B11: 106 | C11: 瓶頸 | D11: 中壢區 | E11: 仁德二街計畫道路 | H11: 45 | I11: 未開闢 | J11: 8 | K11: 0 | L11: 3 | M11: 0 | N11: 0 | O11: 1440000 | P11: 39138120 | Q11: 0 | R11: 40578120 | S11: 通過 | U11: (107.11.9)
A12: 11 | B12: 106 | C12: 瓶頸 | D12: 中壢區 | E12: 榮安八街計畫道路 | H12: 16 | I12: 未開闢 | J12: 8 | K12: 1 | L12: 3 | M12: 0 | N12: 0 | O12: 512000 | P12: 1910400 | Q12: 0 | R12: 2422400 | S12: 通過 | T12: ※王浩宇 | W12: 王浩宇
A13: 12 | B13: 106 | C13: 瓶頸 | D13: 中壢區 | E13: 松智一街 | H13: 50 | I13: 3 | J13: 12 | K13: 3 | L13: 3 | M13: 1 | N13: 1 | O13: 2400000 | P13: 24031052 | Q13: 8019400 | R13: 34450452 | S13: 通過 | T13: ※彭俊豪.李光達.郭麗華.林志強 | W13: 彭俊豪.李光達.郭麗華.林志強
A14: 13 | B14: 106 | C14: 瓶頸 | D14: 中壢區 | E14: 松德路 | H14: 38 | I14: 7 | J14: 12 | K14: 4 | L14: 5 | M14: 2 | N14: 0 | O14: 1824000 | P14: 14749901 | Q14: 5514600 | R14: 22088501 | S14: 通過
A15: 14 | B15: 106 | C15: 瓶頸 | D15: 中壢區 | E15: 榮安五街 | H15: 15 | I15: 2.5 | J15: 8 | K15: 0 | L15: 1 | M15: 0 | N15: 0 | O15: 480000 | P15: 1528320 | Q15: 0 | R15: 2008320 | T15: ※彭俊豪.李光達.郭麗華.林志強 | W15: 彭俊豪.李光達.郭麗華.林志強
A16: 15 | B16: 106 | C16: 瓶頸 | D16: 中壢區 | E16: 環中東路106巷4弄(陸光二街臨自強公園端) 道路瓶頸打通 | H16: 15 | I16: 4.5 | J16: 8 | K16: 4 | L16: 0 | M16: 1 | N16: 0 | O16: 480000 | P16: 0 | Q16: 5555000 | R16: 6035000 | S16: 通過 | U16: (109.2.28)
A17: 16 | B17: 106 | C17: 瓶頸 | D17: 中壢區 | E17: 文化路130巷 | H17: 36 | I17: 2.5~4.5 | J17: 8 | K17: 0 | L17: 5 | M17: 2 | N17: 0 | O17: 1152000 | P17: 16195046 | Q17: 2282600 | R17: 19629646 | U17: (107.11.26)
A18: 17 | B18: 106 | C18: 瓶頸 | D18: 中壢區 | E18: 興仁路二段273巷 | H18: 42 | I18: 2.5~4.5 | J18: 8 | K18: 2 | L18: 5 | M18: 0 | N18: 0 | O18: 1344000 | P18: 10419904 | Q18: 0 | R18: 11763904 | U18: 區公所自辦 (107.5.8)
A19: 18 | B19: 106 | C19: 瓶頸 | D19: 平鎮區 | E19: 南京路(大連街~上海路)拓寬 | H19: 67 | I19: 8 | J19: 15 | K19: 2 | L19: 0 | M19: 0 | N19: 0 | O19: 4020000 | P19: 0 | Q19: 0 | R19: 4020000 | S19: 通過 | T19: ※專案瓶頸 | U19: (107.5.17)
A20: 19 | B20: 106 | C20: 瓶頸 | D20: 平鎮區 | E20: 石門大圳巡防道路改善工程 | H20: 280* | I20: 3.5 | J20: 15 | K20: 22 | L20: 0 | M20: 0 | N20: 0 | O20: 33075454 | P20: 0 | Q20: 0 | R20: 33075454 | S20: 通過 | T20: ※專案瓶頸 ※莊玉輝 | U20: (107.9.6) | W20: 莊玉輝
A21: 20 | B21: 106 | C21: 瓶頸 | D21: 平鎮區 | E21: 貿東路與中正一路拓寬 | H21: 50 | I21: 6 | J21: 15 | K21: 1 | L21: 2 | M21: 0 | N21: 2 | O21: 3000000 | P21: 16749077 | Q21: 1696800 | R21: 21445877 | S21: 通過 | T21: ※謝彰文 | U21: (107.6.19) | W21: 謝彰文
A22: 21 | B22: 106 | C22: 瓶頸 | D22: 平鎮區 | E22: 貿東路66巷與貿中街口拓寬 | H22: 20 | I22: 3.5 | J22: 8 | K22: 0 | L22: 1 | M22: 2 | N22: 1 | O22: 640000 | P22: 3014382.5 | Q22: 3878400 | R22: 7532782.5 | S22: 通過 | T22: ※謝彰文 | W22: 謝彰文
A23: 22 | B23: 106 | C23: 瓶頸 | D23: 平鎮區 | E23: 打通南安路60巷與南京路111巷道路 | H23: 20 | I23: 未開闢 | J23: 8 | K23: 0 | L23: 2 | M23: 0 | N23: 0 | O23: 640000 | P23: 23806797 | Q23: 0 | R23: 24446797 | T23: ※金星里辦公處 | U23: (111.10.20) | W23: 金星里辦公處
A24: 23 | B24: 106 | C24: 瓶頸 | D24: 平鎮區 | E24: 龍安路與平東路口道路拓寬工程 | H24: 50 | I24: 未開闢 | J24: 15 | K24: 0 | L24: 11 | M24: 0 | N24: 4 | O24: 3000000 | P24: 67959104 | Q24: 4848000 | R24: 75807104
A25: 24 | B25: 106 | C25: 瓶頸 | D25: 平鎮區 | E25: 太平東路、西路與洪圳路口拓寬工程 | H25: 43 | I25: 6 | J25: 6 | K25: 8 | L25: 2 | M25: 9 | N25: 0 | O25: 1032000 | P25: 2181902.4 | Q25: 14948000 | R25: 18161902
A26: 25 | B26: 106 | C26: 瓶頸 | D26: 平鎮區 | E26: 雙連三段與雙榮路路口道路拓寬工程 | H26: 31 | I26: 6 | J26: 15 | K26: 0 | L26: 6 | M26: 2 | N26: 2 | O26: 1860000 | P26: 34418385 | Q26: 18907200 | R26: 55185585 | S26: 通過
A27: 26 | B27: 106 | C27: 瓶頸 | D27: 平鎮區 | E27: 新華路打通平東路239巷51弄(社子3A池旁) | H27: 28 | I27: 未開闢 | J27: 15 | K27: 2 | L27: 3 | M27: 0 | N27: 0 | O27: 1680000 | P27: 42961068 | Q27: 0 | R27: 44641068 | S27: 通過 | T27: ※舒翠玲.謝彰文 | U27: (108.7.14) | W27: 舒翠玲.謝彰文
A28: 27 | B28: 106 | C28: 瓶頸 | D28: 八德區 | E28: 龍祥街路口改善 | H28: 50 | I28: 8 | J28: 12 | K28: 4 | L28: 2 | M28: 0 | N28: 1 | O28: 2400000 | P28: 20118963 | Q28: 606000 | R28: 23124963 | S28: 通過 | T28: ※市長 | U28: (110.1.18) | W28: 市長
A29: 28 | B29: 106 | C29: 瓶頸 | D29: 八德區 | E29: 忠勇街424巷新建 | H29: 45 | I29: 未開闢 | J29: 8 | K29: 1 | L29: 4 | M29: 0 | N29: 0 | O29: 1440000 | P29: 13334755 | Q29: 1515000 | R29: 16289755 | S29: 通過 | U29: (107.5.28)
A30: 29 | B30: 106 | C30: 瓶頸 | D30: 八德區 | E30: 建國路91巷暨相鄰計畫道路 | H30: 50 | I30: 未開闢 | J30: 8 | K30: 2 | L30: 1 | M30: 0 | N30: 0 | O30: 1600000 | P30: 8495347.6 | Q30: 0 | R30: 10095348 | S30: 通過 | U30: (110.9.2)
A31: 30 | B31: 106 | C31: 瓶頸 | D31: 楊梅區 | E31: 永美路445巷 | H31: 42 | I31: 未開闢 | J31: 12 | K31: 4 | L31: 9 | M31: 1 | N31: 0 | O31: 2016000 | P31: 15035753 | Q31: 6767000 | R31: 23818753 | S31: 通過 | T31: ※周玉琴 | W31: 周玉琴
A32: 31 | B32: 106 | C32: 瓶頸 | D32: 蘆竹區 | E32: 開南段龍林街 | H32: 160* | I32: 未開闢 | J32: 6 | K32: 14 | L32: 0 | M32: 0 | N32: 0 | O32: 3840000 | P32: 0 | Q32: 0 | R32: 3840000 | S32: 通過 | T32: ※專案瓶頸 ※郭麗華 | U32: (112.1.3) | W32: 郭麗華
A33: 32 | B33: 106 | C33: 瓶頸 | D33: 蘆竹區 | E33: 後面坑路靠山林路段道路拓寬 | H33: 25 | I33: 3 | J33: 5 | K33: 2 | L33: 6 | M33: 0 | N33: 0 | O33: 500000 | P33: 29218320 | Q33: 9090000 | R33: 38808320
A34: 33 | B34: 106 | C34: 瓶頸 | D34: 蘆竹區 | E34: 打通營盤里歐楓街末端路段 | H34: 150* | I34: 未開闢 | J34: 9 | K34: 6 | L34: 0 | M34: 0 | N34: 0 | O34: 3900000 | P34: 78573487 | Q34: 0 | R34: 82473487 | S34: 通過 | T34: ※有償撥用抵稅地 | U34: (108.1.28)
A35: 34 | B35: 106 | C35: 瓶頸 | D35: 蘆竹區 | E35: 南順五街道路瓶頸打通 | H35: 16 | I35: 4 | J35: 8 | K35: 0 | L35: 1 | M35: 0 | N35: 0 | O35: 512000 | P35: 9650440.8 | Q35: 0 | R35: 10162441 | S35: 通過
A36: 35 | B36: 106 | C36: 瓶頸 | D36: 大溪區 | E36: 鄉道桃64線道路拓寬 | H36: 150* | I36: 5 | J36: 6 | K36: 2 | L36: 4 | M36: 0 | N36: 0 | O36: 3600000 | P36: 4431600 | Q36: 0 | R36: 8031600 | S36: 通過 | T36: ※李柏坊.陳治文 | W36: 李柏坊.陳治文
A37: 36 | B37: 106 | C37: 瓶頸 | D37: 大園區 | E37: 和平二街拓寬 | H37: 50 | I37: 4 | J37: 8 | K37: 5 | L37: 5 | M37: 0 | N37: 1 | O37: 1600000 | P37: 29199780 | Q37: 2908800 | R37: 33708580
A38: 37 | B38: 106 | C38: 瓶頸 | D38: 大園區 | E38: 田心里33鄰與華興路口 | H38: 50 | I38: 6~8 | J38: 8 | K38: 0 | L38: 3 | M38: 0 | N38: 0 | O38: 1600000 | P38: 2375683.2 | Q38: 0 | R38: 3975683.2 | S38: 通過 | T38: ※徐其萬 | U38: (109.2.20) | W38: 徐其萬
A39: 38 | B39: 106 | C39: 瓶頸 | D39: 大園區 | E39: 文化街至中正東路(兒一公園) | H39: 40 | I39: 未開闢 | J39: 8 | K39: 1 | L39: 2 | M39: 0 | N39: 1 | S39: 保留執行 (106.5.24) | T39: ※原(兒一公園)中正東路10巷15弄前之替代方案
A40: 39 | B40: 106 | C40: 瓶頸 | D40: 龜山區 | E40: 湖山街拓寬 | H40: 80* | I40: 4.5 | J40: 8 | K40: 6 | L40: 0 | M40: 0 | N40: 0 | O40: 2560000 | P40: 0 | Q40: 0 | R40: 2560000 | S40: 通過 | T40: ※專案瓶頸 ※林正峰 | U40: (109.6.8) | W40: 林正峰
...

Sheet 2.專案函文紀錄
A1: 序 | B1: 發文單位 | C1: 受文單位 | D1: 發文日期 | E1: 文號函 | F1: 公文主旨 | G1: 簡要說明(乾坤備註) | H1: 工程名稱/作業事項 | I1: 作業類別 | J1: 派工單備註/分案名稱 | K1: 派工單號 | L1: 履約期限 | M1: 公文檔案名稱 | N1: 案件承辦 | O1: 查估單位 | P1: 案件雲端路徑 | Q1: 作業資料夾
B2: 桃園市政府工務局 | C2: 乾坤測繪科技有限公司 | D2: 114年07月25日 | E2: 桃工用字第1140030087號 | F2: AAAAAA(測試) | G2: 中壢區大華路(內定一街至大華路350巷)道路拓寬工程_土地徵收市價查估作業 | H2: 中壢區大華路(內定一街至大華路350巷)(都外) | I2: 02.土地協議市價查估作業 | J2: 中壢區大華路(內定一街至大華路350巷)道路拓寬工程_土地徵收市價查估作業 | K2: 112_派工單號104 | L2: 2025/8/5前提送 | P2: https://reurl.cc/8bzjR4
B3: 桃園市政府工務局 | C3: 乾坤測繪科技有限公司 | D3: 114年07月24日 | E3: 桃工用字第9999999號(測試) | F3: BBBBBBBB(測試) | G3: B1111111111(測試) | H3: 中壢區大華路(內定一街至大華路350巷)(都外) | J3: 中壢區大華路(內定一街至大華路350巷)道路拓寬工程_土地徵收市價查估作業
B4: 桃園市政府工務局 | C4: 乾坤測繪科技有限公司 | D4: 114年07月25日 | E4: 桃工用字第1140030087號 | F4: CCCCCCCCCCC(測試) | G4: 中壢區成功路94巷至122巷道路拓寬工程_土地徵收市價查估作業 | H4: 中壢區成功路94巷至122巷間道路拓寬 | I4: 03.土地徵收市價查估作業 | J4: 中壢區成功路94巷至122巷道路拓寬工程_土地徵收市價查估作業 | K4: 112_派工單號105 | L4: 2025/8/5前提送
A5: 1 | B5: 桃園市政府工務局 | C5: 乾坤測繪科技有限公司 | D5: 45994 | E5: 桃工用字第11400491701號 | F5: 開會事由:「115年度桃園市興辦公共設施用地取得所需土地市價及地上物查估、測量作業曁開瓶資料製作委託專業服務(開口契約)」評選會議(廠商備詢) 開會時間:中華民國114年12月8日(星期一)下午1時30分 開會地點:桃園市綜合會議廳202會議室(桃園市桃園區縣府路11號2楼) | G5: 通知專業服務評選會議 | I5: 00.專案會議 | L5: 評選會議:114年12月8日(星期一)下午1時30分 | M5: 114年12月03日_桃工用字第11400491701號_通知專業服務評選會議.pdf
A6: 2 | B6: 桃園市政府工務局 | C6: 乾坤測繪科技有限公司 | D6: 46007 | E6: 桃工用字第11400504761號 | F6: 為辦理「115年度桃園市興辦公共設施用地取得所需土地市價及地上物查估、測量作業暨開瓶資料製作委託專業服務(開口契約)」採購案議約作業，請派員出席參加，請查照。 | G6: 通知採購案議約作業 | I6: 00.專案會議 | L6: 議約作業:114年12月18日(星期四)下午3時30分 | M6: 114年12月16日_桃工用字第11400504761號_通知採購案議約作業.pdf
A7: 3 | B7: 乾坤測繪科技有限公司 | C7: 桃園市政府工務局 | D7: 46010 | E7: 桃工採字第1140052379號 | F7: 檢送「115年度桃園市興辦公共設施用地取得所需土地市價及地上物查估、測量作業曁開瓶資料製作委託專業服務(開口契約)」(1141106-2)第1次限制性招標決標公告1份,請查照。 | G7: 檢送限制性招標決標公告 | I7: #.專案行政作業
A8: 4 | B8: 乾坤測繪科技有限公司 | C8: 桃園市政府工務局 | D8: 46022 | E8: 乾坤測字第1140000214號 | F8: 檢送「115年度桃園市興辦公共設施用地取得所需土地市價及地上物查估、測量作業暨開瓶資料製作委託專業服務(開口契約)」專業責任保險及雇主意外責任險保單正本、保險費收據副本各1份，請查照。 | G8: 檢送雇主意外責任險、專業責任保險單及收據 | I8: #.專案行政作業
A9: 5 | B9: 乾坤測繪科技有限公司 | C9: 桃園市政府工務局 | D9: 46022 | E9: 乾坤測字第1140000213號 | F9: 檢送「115年度桃園市興辦公共設施用地取得所需土地市價及地上物查估、測量作業暨開瓶資料製作委託專業服務(開口契約)」(標案案號：1141106-2)契約書正本2份、副本8份，請查照。 | G9: 檢送契約書正本2份、副本8份 | I9: #.專案行政作業
A10: 6 | B10: 乾坤測繪科技有限公司 | C10: 桃園市政府工務局 | D10: 115年01月05日 | E10: 乾坤測字第1150000002號 | F10: 檢送「115年度桃園市興辦公共設施用地取得所需土地市價及地上物查估、測量作業暨開瓶資料製作委託專業服務(開口契約)案」之系統建置作業工作計畫書乙式10份，請查照。 | G10: 檢送工作計畫書乙式10份 | I10: 08.作業提繳事項
A11: 7 | B11: 桃園市政府工務局 | C11: 乾坤測繪科技有限公司 | D11: 115年01月05日 | E11: 桃工用字第1150000279號 | F11: 有關「115年度桃園市興辦公共設施用地取得所需土地市價及地上物查估、测量作業曁開瓶資料製作委託專業服務(開口契約)」115年度第1次教育訓練一案,詳如說明,請查照惠復。 | G11: 通知辦理115年_派工單號001 | H11: 115年度第1次教育訓練 | I11: 07.辦理教育訓練 | J11: =_xlfn.CONCAT(H11,+"_",I11) -> 115年度第1次教育訓練_07.辦理教育訓練 | K11: 115年_派工單號001 | L11: 115年01月15日前函覆 | P11: https://reurl.cc/rKo52Z | Q11: Z:\03.專案管控專區\桃園市政府\桃園市政府工務局\2025\115年桃園市興辦公共設施用地取得專業服務\04.專案工作事項\01.派工案件管控\1.各派工案辦理紀錄\115年_派工單號001\
A12: 8 | B12: 乾坤測繪科技有限公司 | C12: 桃園市政府工務局 | D12: 115年01月09日 | E12: 乾坤測字第1150000003號 | F12: 檢送「115年度桃園市興辦公共設施用地取得所需土地市價及地上物查估、測量作業暨開瓶資料製作委託專業服務(開口契約)」第1次教育訓練計畫書1份，請查照。 | G12: 檢送第1次教育訓練計畫書1份 | I12: #.專案行政作業
A13: 9 | B13: 桃園市政府工務局 | C13: 乾坤測繪科技有限公司 | D13: 115年01月13日 | E13: 桃工用字第1150002017號 | F13: 有關貴公司檢送「115年度桃園市興辦公共設施用地取得所需土地市價及地上查估、測量作業暨開瓶資料製作委託專業服務（開口契約）」雇主意外責任險、專業責任保險單及收據，本局同意備查，請查照。 | G13: 通知雇主意外責任險、專業責任保險單及收據同意備查 | I13: #.專案行政作業
A14: 10 | B14: 桃園市政府工務局 | C14: 乾坤測繪科技有限公司 | D14: 115年01月15日 | E14: 桃工用字第1150001581號 | F14: 有關貴公司所提「115年度桃園市興辦公共設施用地取得所需土地市價及地上物查估、測量作業暨開瓶資料製作委託專業服務(開口契約)」教育訓練計畫書一案，本局原則同意核定，請查照。 | G14: 通知教育訓練計畫書同意核定 | I14: #.專案行政作業 | L14: 115年01月23日辦理
A15: 11 | B15: 桃園市政府工務局 | C15: 乾坤測繪科技有限公司 | D15: 115年01月15日 | E15: 桃工用字第1150001582號 | F15: 主旨:檢送「115年度桃園市興辦公共設施用地取得所需土地市價及地上物查估、測量作業曁開瓶資料製作委託專業服務(開口契約)」派工單(002)1份,詳如說明,請查照惠復。 | G15: 通知辦理115年_派工單號002 | H15: 桃園市八德區霄裡公園及周邊道路興闢工程 | I15: 02.土地協議市價查估作業 | J15: =_xlfn.CONCAT(H15,+"_",I15) -> 桃園市八德區霄裡公園及周邊道路興闢工程_02.土地協議市價查估作業 | K15: 115年_派工單號002 | L15: 115年02月08日前函覆(發文日起25日歷天内檢送成果) | M15: =_xlfn.CONCAT(D15,+"_",E5,+"_",G15) -> 115年01月15日_桃工用字第11400491701號_通知辦理115年_派工單號002 | N15: 行政助理 粘亞溱 | O15: 昇揚估價師 欒中文 | P15: https://reurl.cc/EbM8Dm | Q15: Z:\03.專案管控專區\桃園市政府\桃園市政府工務局\2025\115年桃園市興辦公共設施用地取得專業服務\04.專案工作事項\01.派工案件管控\1.各派工案辦理紀錄\115年_派工單號002\
B16: 桃園市政府工務局 | C16: 乾坤測繪科技有限公司 | D16: 115年01月14日 | E16: 桃工用字第1150002112號 | F16: 為貴公司承攬本局「115年度桃園市興辦公共設施用地取得所需土地市價及地上物查估、測量作業曁開瓶資料製作委託專業服務(開口契約)」一案,詳如說明,請查照。 說明: 一、依據旨揭案號1141106-2勞務採購契約書辦理。 二、本次委託事項為「中壢區龍岡路4-1-10M計畫道路路口瓶頸 打通工程」案内協議價購市價查估作業,請貴公司依契約規定於25日曆天(115年2月13日)前檢送查估成果報告書。 三、檢附派工單1份,請於正本用印擲回,並自行留存副本,以便後續驗收事宜。 | G16: 通知辦理115年_派工單號003 | H16: 中壢區龍岡路4-1-10M計畫道路路口瓶頸打通工程 | I16: 02.土地協議市價查估作業 | J16: =_xlfn.CONCAT(H16,+"_",I16) -> 中壢區龍岡路4-1-10M計畫道路路口瓶頸打通工程_02.土地協議市價查估作業 | K16: 115年_派工單號003 | L16: 115年02月23日前函覆(發文日起25日歷天内檢送成果) | M16: =_xlfn.CONCAT(D16,+"_",E6,+"_",G16) -> 115年01月14日_桃工用字第11400504761號_通知辦理115年_派工單號003 | N16: 約催助理 吳佳芸 | O16: 全國估價師 張子亮 | P16: https://reurl.cc/rKjOr1 | Q16: Z:\03.專案管控專區\桃園市政府\桃園市政府工務局\2025\115年桃園市興辦公共設施用地取得專業服務\04.專案工作事項\01.派工案件管控\1.各派工案辦理紀錄\115年_派工單號003\

Sheet 3.年度派工紀錄
A1: 序 | B1: 派工單號 | C1: 機關函文號 | D1: 工程名稱/派工事項 | E1: 作業類別 | F1: 分案名稱/派工備註 | G1: 履約期限 | H1: 案件承辦 | I1: 查估單位 | J1: 乾坤函文號 | K1: 雲端資料夾 | L1: 專案資料夾 | M1: 聯絡備註 | N1: 機關函文歷程(對應工程名稱) | O1: 機關函文歷程(對應工程名稱+主旨) | P1: 乾坤函文紀錄(對應工程名稱) | Q1: 乾坤函文歷程(對應工程名稱+主旨)
A3: 1 | B3: 115年_派工單號001 | C3: =IF(B3="","",_xlfn.XLOOKUP(B3,'2.專案函文紀錄'!K:K,'2.專案函文紀錄'!E:E,"查無此案紀錄",0)) -> 桃工用字第1150000279號 | D3: =IF(B3="","",_xlfn.XLOOKUP(B3,'2.專案函文紀錄'!K:K,'2.專案函文紀錄'!H:H,"查無此案紀錄",0)) -> 115年度第1次教育訓練 | E3: =IF(B3="","",_xlfn.XLOOKUP(B3,'2.專案函文紀錄'!K:K,'2.專案函文紀錄'!I:I,"查無此案紀錄",0)) -> 07.辦理教育訓練 | F3: =IF(B3="","",_xlfn.XLOOKUP(B3,'2.專案函文紀錄'!K:K,'2.專案函文紀錄'!J:J,"查無此案紀錄",0)) -> 115年度第1次教育訓練_07.辦理教育訓練 | G3: =IF(B3="","",_xlfn.XLOOKUP(B3,'2.專案函文紀錄'!K:K,'2.專案函文紀錄'!L:L,"查無此案紀錄",0)) -> 115年01月15日前函覆 | I3: =IF(B3="","",_xlfn.XLOOKUP(B3,'2.專案函文紀錄'!K:K,'2.專案函文紀錄'!O:O,"查無此案紀錄",0)) -> 0 | J3: 乾坤測字第1150000003號 | K3: =IF(B3="","",_xlfn.XLOOKUP(B3,'2.專案函文紀錄'!K:K,'2.專案函文紀錄'!P:P,"查無此案紀錄",0)) -> https://reurl.cc/rKo52Z | L3: =IF(B3="","",_xlfn.XLOOKUP(B3,'2.專案函文紀錄'!K:K,'2.專案函文紀錄'!Q:Q,"查無此案紀錄",0)) -> Z:\03.專案管控專區\桃園市政府\桃園市政府工務局\2025\115年桃園市興辦公共設施用地取得專業服務\04.專案工作事項\01.派工案件管控\1.各派工案辦理紀錄\115年_派工單號001\ | N3: {=_xlfn.TEXTJOIN("、", TRUE, _xlfn._xlws.FILTER(IF('2.專案函文紀錄'!$D$2:$D$99="", "", '2.專案函文紀錄'!$D$2:$D$99 & "_" & '2.專案函文紀錄'!$E$2:$E$99), ('2.專案函文紀錄'!$H$2:$H$99 = D3) * ('2.專案函文紀錄'!$B$2:$B$99 = "桃園市政府工務局") * ('2.專案函文紀錄'!$D$2:$D$99 <> "查無此案紀錄"), ""))} -> 115年01月05日_桃工用字第1150000279號 | O3: {=_xlfn.TEXTJOIN(CHAR(10), TRUE, _xlfn._xlws.FILTER(IF('2.專案函文紀錄'!$D$2:$D$99="", "", '2.專案函文紀錄'!$D$2:$D$99 & "_" & '2.專案函文紀錄'!$E$2:$E$99 & "_" & '2.專案函文紀錄'!$G$2:$G$99), ('2.專案函文紀錄'!$H$2:$H$99 = D3) * ('2.專案函文紀錄'!$B$2:$B$99 = "桃園市政府工務局") * ('2.專案函文紀錄'!$D$2:$D$99 <> "查無此案紀錄"), ""))} -> 115年01月05日_桃工用字第1150000279號_通知辦理115年_派工單號001 | P3: {=_xlfn.TEXTJOIN("、", TRUE, _xlfn._xlws.FILTER(IF('2.專案函文紀錄'!$D$2:$D$99="", "", '2.專案函文紀錄'!$D$2:$D$99 & "_" & '2.專案函文紀錄'!$E$2:$E$99), ('2.專案函文紀錄'!$H$2:$H$99 = E3) * ('2.專案函文紀錄'!$B$2:$B$99 = "乾坤測繪科技有限公司") * ('2.專案函文紀錄'!$D$2:$D$99 <> "查無此案紀錄"), ""))} | Q3: {=_xlfn.TEXTJOIN(CHAR(10), TRUE, _xlfn._xlws.FILTER(IF('2.專案函文紀錄'!$D$2:$D$99="", "", '2.專案函文紀錄'!$D$2:$D$99 & "_" & '2.專案函文紀錄'!$E$2:$E$99 & "_" & '2.專案函文紀錄'!$G$2:$G$99), ('2.專案函文紀錄'!$H$2:$H$99 = E3) * ('2.專案函文紀錄'!$B$2:$B$99 = "乾坤測繪科技有限公司") * ('2.專案函文紀錄'!$D$2:$D$99 <> "查無此案紀錄"), ""))}
A4: 2 | B4: 115年_派工單號002 | C4: =IF(B4="","",_xlfn.XLOOKUP(B4,'2.專案函文紀錄'!K:K,'2.專案函文紀錄'!E:E,"查無此案紀錄",0)) -> 桃工用字第1150001582號 | D4: =IF(B4="","",_xlfn.XLOOKUP(B4,'2.專案函文紀錄'!K:K,'2.專案函文紀錄'!H:H,"查無此案紀錄",0)) -> 桃園市八德區霄裡公園及周邊道路興闢工程 | E4: =IF(B4="","",_xlfn.XLOOKUP(B4,'2.專案函文紀錄'!K:K,'2.專案函文紀錄'!I:I,"查無此案紀錄",0)) -> 02.土地協議市價查估作業 | F4: =IF(B4="","",_xlfn.XLOOKUP(B4,'2.專案函文紀錄'!K:K,'2.專案函文紀錄'!J:J,"查無此案紀錄",0)) -> 桃園市八德區霄裡公園及周邊道路興闢工程_02.土地協議市價查估作業 | G4: =IF(B4="","",_xlfn.XLOOKUP(B4,'2.專案函文紀錄'!K:K,'2.專案函文紀錄'!L:L,"查無此案紀錄",0)) -> 115年02月08日前函覆(發文日起25日歷天内檢送成果) | H4: =IF(B4="","",_xlfn.XLOOKUP(B4,'2.專案函文紀錄'!K:K,'2.專案函文紀錄'!N:N,"查無此案紀錄",0)) -> 行政助理 粘亞溱 | I4: =IF(B4="","",_xlfn.XLOOKUP(B4,'2.專案函文紀錄'!K:K,'2.專案函文紀錄'!O:O,"查無此案紀錄",0)) -> 昇揚估價師 欒中文 | K4: =IF(B4="","",_xlfn.XLOOKUP(B4,'2.專案函文紀錄'!K:K,'2.專案函文紀錄'!P:P,"查無此案紀錄",0)) -> https://reurl.cc/EbM8Dm | L4: =IF(B4="","",_xlfn.XLOOKUP(B4,'2.專案函文紀錄'!K:K,'2.專案函文紀錄'!Q:Q,"查無此案紀錄",0)) -> Z:\03.專案管控專區\桃園市政府\桃園市政府工務局\2025\115年桃園市興辦公共設施用地取得專業服務\04.專案工作事項\01.派工案件管控\1.各派工案辦理紀錄\115年_派工單號002\ | M4: 2026.01.16 星期五 19:23 (桃園工務局)粘亞溱小姐 請駿穠上班再讀 派工單(002)「桃園市八德區霄裡公園及周邊道路興闢工程」土地協議及徵收市價查估作業 1.本案基本資料如上檔，後續其他需求還請不吝連繫告知 (有的謄本是去年的，會影響嗎，如果需要最新版再跟我說) 2.本案為市立醫院案，長官視同1案，目前還是公園用地，未來會都變 3.徵收因興辦事業計畫等因素，需製作成2案，分別為道路用地1案、公園用地1案 4.上述需補充說明或不瞭解的地方，於上班時段方便接電話溝通時，請先訊息通知我後，由我致給給你 以上，謝謝駿穠 | N4: {=_xlfn.TEXTJOIN("、", TRUE, _xlfn._xlws.FILTER(IF('2.專案函文紀錄'!$D$2:$D$99="", "", '2.專案函文紀錄'!$D$2:$D$99 & "_" & '2.專案函文紀錄'!$E$2:$E$99), ('2.專案函文紀錄'!$H$2:$H$99 = D4) * ('2.專案函文紀錄'!$B$2:$B$99 = "桃園市政府工務局") * ('2.專案函文紀錄'!$D$2:$D$99 <> "查無此案紀錄"), ""))} -> 115年01月15日_桃工用字第1150001582號 | O4: {=_xlfn.TEXTJOIN(CHAR(10), TRUE, _xlfn._xlws.FILTER(IF('2.專案函文紀錄'!$D$2:$D$99="", "", '2.專案函文紀錄'!$D$2:$D$99 & "_" & '2.專案函文紀錄'!$E$2:$E$99 & "_" & '2.專案函文紀錄'!$G$2:$G$99), ('2.專案函文紀錄'!$H$2:$H$99 = D4) * ('2.專案函文紀錄'!$B$2:$B$99 = "桃園市政府工務局") * ('2.專案函文紀錄'!$D$2:$D$99 <> "查無此案紀錄"), ""))} -> 115年01月15日_桃工用字第1150001582號_通知辦理115年_派工單號002 | P4: {=_xlfn.TEXTJOIN("、", TRUE, _xlfn._xlws.FILTER(IF('2.專案函文紀錄'!$D$2:$D$99="", "", '2.專案函文紀錄'!$D$2:$D$99 & "_" & '2.專案函文紀錄'!$E$2:$E$99), ('2.專案函文紀錄'!$H$2:$H$99 = E4) * ('2.專案函文紀錄'!$B$2:$B$99 = "乾坤測繪科技有限公司") * ('2.專案函文紀錄'!$D$2:$D$99 <> "查無此案紀錄"), ""))} | Q4: {=_xlfn.TEXTJOIN(CHAR(10), TRUE, _xlfn._xlws.FILTER(IF('2.專案函文紀錄'!$D$2:$D$99="", "", '2.專案函文紀錄'!$D$2:$D$99 & "_" & '2.專案函文紀錄'!$E$2:$E$99 & "_" & '2.專案函文紀錄'!$G$2:$G$99), ('2.專案函文紀錄'!$H$2:$H$99 = E4) * ('2.專案函文紀錄'!$B$2:$B$99 = "乾坤測繪科技有限公司") * ('2.專案函文紀錄'!$D$2:$D$99 <> "查無此案紀錄"), ""))}
A5: 3 | B5: 115年_派工單號003 | C5: =IF(B5="","",_xlfn.XLOOKUP(B5,'2.專案函文紀錄'!K:K,'2.專案函文紀錄'!E:E,"查無此案紀錄",0)) -> 桃工用字第1150002112號 | D5: =IF(B5="","",_xlfn.XLOOKUP(B5,'2.專案函文紀錄'!K:K,'2.專案函文紀錄'!H:H,"查無此案紀錄",0)) -> 中壢區龍岡路4-1-10M計畫道路路口瓶頸打通工程 | E5: =IF(B5="","",_xlfn.XLOOKUP(B5,'2.專案函文紀錄'!K:K,'2.專案函文紀錄'!I:I,"查無此案紀錄",0)) -> 02.土地協議市價查估作業 | F5: =IF(B5="","",_xlfn.XLOOKUP(B5,'2.專案函文紀錄'!K:K,'2.專案函文紀錄'!G:G,"查無此案紀錄",0)) -> 通知辦理115年_派工單號003 | G5: =IF(B5="","",_xlfn.XLOOKUP(B5,'2.專案函文紀錄'!K:K,'2.專案函文紀錄'!L:L,"查無此案紀錄",0)) -> 115年02月23日前函覆(發文日起25日歷天内檢送成果) | H5: =IF(B5="","",_xlfn.XLOOKUP(B5,'2.專案函文紀錄'!K:K,'2.專案函文紀錄'!N:N,"查無此案紀錄",0)) -> 約催助理 吳佳芸 | I5: =IF(B5="","",_xlfn.XLOOKUP(B5,'2.專案函文紀錄'!K:K,'2.專案函文紀錄'!O:O,"查無此案紀錄",0)) -> 全國估價師 張子亮 | K5: =IF(B5="","",_xlfn.XLOOKUP(B5,'2.專案函文紀錄'!K:K,'2.專案函文紀錄'!P:P,"查無此案紀錄",0)) -> https://reurl.cc/rKjOr1 | L5: =IF(B5="","",_xlfn.XLOOKUP(B5,'2.專案函文紀錄'!K:K,'2.專案函文紀錄'!Q:Q,"查無此案紀錄",0)) -> Z:\03.專案管控專區\桃園市政府\桃園市政府工務局\2025\115年桃園市興辦公共設施用地取得專業服務\04.專案工作事項\01.派工案件管控\1.各派工案辦理紀錄\115年_派工單號003\ | M5: 2026.01.20 星期二 09:05 (桃園工務局)吳佳芸小姐 「中壢區龍岡路4-1-10M計畫道路路口瓶頸打通工程」 這案徵收市價由張子亮估價師承辦為統一 請協議市價一由張估辦理
A6: 4 | D6: =IF(B6="","",_xlfn.XLOOKUP(B6,#REF!,#REF!,"查無此案名(工程名稱)", 0)) | F6: =IF(B6="","",_xlfn.XLOOKUP(B6,'2.專案函文紀錄'!K:K,'2.專案函文紀錄'!G:G,"查無此案紀錄",0)) | G6: =IF(B6="","",_xlfn.XLOOKUP(B6,'2.專案函文紀錄'!K:K,'2.專案函文紀錄'!L:L,"查無此案紀錄",0)) | I6: =IF(B6="","",_xlfn.XLOOKUP(B6,#REF!,#REF!,"查無此紀錄",0)) | K6: =IF(B6="","",_xlfn.XLOOKUP(B6,'2.專案函文紀錄'!K:K,'2.專案函文紀錄'!P:P,"查無此案紀錄",0))
A7: 5 | D7: =IF(B7="","",_xlfn.XLOOKUP(B7,#REF!,#REF!,"查無此案名(工程名稱)", 0)) | F7: =IF(B7="","",_xlfn.XLOOKUP(B7,'2.專案函文紀錄'!K:K,'2.專案函文紀錄'!G:G,"查無此案紀錄",0)) | G7: =IF(B7="","",_xlfn.XLOOKUP(B7,'2.專案函文紀錄'!K:K,'2.專案函文紀錄'!L:L,"查無此案紀錄",0)) | I7: =IF(B7="","",_xlfn.XLOOKUP(B7,#REF!,#REF!,"查無此紀錄",0)) | K7: =IF(B7="","",_xlfn.XLOOKUP(B7,'2.專案函文紀錄'!K:K,'2.專案函文紀錄'!P:P,"查無此案紀錄",0))
A8: 6 | D8: =IF(B8="","",_xlfn.XLOOKUP(B8,#REF!,#REF!,"查無此案名(工程名稱)", 0)) | F8: =IF(B8="","",_xlfn.XLOOKUP(B8,'2.專案函文紀錄'!K:K,'2.專案函文紀錄'!G:G,"查無此案紀錄",0)) | G8: =IF(B8="","",_xlfn.XLOOKUP(B8,'2.專案函文紀錄'!K:K,'2.專案函文紀錄'!L:L,"查無此案紀錄",0)) | I8: =IF(B8="","",_xlfn.XLOOKUP(B8,#REF!,#REF!,"查無此紀錄",0)) | K8: =IF(B8="","",_xlfn.XLOOKUP(B8,'2.專案函文紀錄'!K:K,'2.專案函文紀錄'!P:P,"查無此案紀錄",0))
A9: 7 | D9: =IF(B9="","",_xlfn.XLOOKUP(B9,#REF!,#REF!,"查無此案名(工程名稱)", 0)) | F9: =IF(B9="","",_xlfn.XLOOKUP(B9,'2.專案函文紀錄'!K:K,'2.專案函文紀錄'!G:G,"查無此案紀錄",0)) | G9: =IF(B9="","",_xlfn.XLOOKUP(B9,'2.專案函文紀錄'!K:K,'2.專案函文紀錄'!L:L,"查無此案紀錄",0)) | I9: =IF(B9="","",_xlfn.XLOOKUP(B9,#REF!,#REF!,"查無此紀錄",0)) | K9: =IF(B9="","",_xlfn.XLOOKUP(B9,'2.專案函文紀錄'!K:K,'2.專案函文紀錄'!P:P,"查無此案紀錄",0))
A10: 8 | F10: =IF(B10="","",_xlfn.XLOOKUP(B10,'2.專案函文紀錄'!K:K,'2.專案函文紀錄'!G:G,"查無此案紀錄",0)) | G10: =IF(B10="","",_xlfn.XLOOKUP(B10,'2.專案函文紀錄'!K:K,'2.專案函文紀錄'!L:L,"查無此案紀錄",0)) | I10: =IF(B10="","",_xlfn.XLOOKUP(B10,#REF!,#REF!,"查無此紀錄",0)) | K10: =IF(B10="","",_xlfn.XLOOKUP(B10,'2.專案函文紀錄'!K:K,'2.專案函文紀錄'!P:P,"查無此案紀錄",0))
A11: 9
A12: 10
A13: 11
A14: 12
A15: 13
A16: 14
A17: 15
A18: 16
A19: 17
A20: 18
A21: 19
A22: 20
... A44: 42

Sheet 4.契金管控紀錄
A1: 序 | B1: 派工單號 | C1: 工程名稱/派工事項 | D1: 作業類別 | E1: 分案名稱/派工備註 | F1: 案件承辦 | G1: 查估單位 | H1: 雲端資料夾 | I1: 專案資料夾 | J1: 機關函文歷程(對應工程名稱) | K1: 機關函文歷程(對應工程名稱+主旨) | L1: 乾坤函文紀錄(對應工程名稱) | M1: 乾坤函文歷程(對應工程名稱+主旨) | N1: 01.地上物查估作業 | P1: 02.土地協議市價查估作業 | R1: 03.土地徵收市價查估作業 | T1: 04.相關計畫書製作 | V1: 05.測量作業 | X1: 06.樁位測釘作業 | Z1: 07.辦理教育訓練 | AB1: 本次派工金額 | AC1: 累進派工金額 | AD1: 剩餘金額 | AE1: 完成驗收日期
N2: 派工日期 | O2: 派工金額 | P2: 派工日期 | Q2: 派工金額 | R2: 派工日期 | S2: 派工金額 | T2: 派工日期 | U2: 派工金額 | V2: 派工日期 | W2: 派工金額 | X2: 派工日期 | Y2: 派工金額 | Z2: 派工日期 | AA2: 派工金額
A3: 1 | B3: 115年_派工單號001 | C3: =IF(B3="","",_xlfn.XLOOKUP(B3,'2.專案函文紀錄'!K:K,'2.專案函文紀錄'!H:H,"查無此案紀錄",0)) -> 115年度第1次教育訓練 | D3: =IF(B3="","",_xlfn.XLOOKUP(B3,'2.專案函文紀錄'!K:K,'2.專案函文紀錄'!I:I,"查無此案紀錄",0)) -> 07.辦理教育訓練 | E3: =IF(B3="","",_xlfn.XLOOKUP(B3,'2.專案函文紀錄'!K:K,'2.專案函文紀錄'!J:J,"查無此案紀錄",0)) -> 115年度第1次教育訓練_07.辦理教育訓練 | F3: =IF(B3="","",_xlfn.XLOOKUP(B3,'2.專案函文紀錄'!K:K,'2.專案函文紀錄'!N:N,"查無此案紀錄",0)) -> 0 | G3: =IF(B3="","",_xlfn.XLOOKUP(B3,'2.專案函文紀錄'!K:K,'2.專案函文紀錄'!O:O,"查無此案紀錄",0)) -> 0 | H3: =IF(B3="","",_xlfn.XLOOKUP(B3,'2.專案函文紀錄'!K:K,'2.專案函文紀錄'!P:P,"查無此案紀錄",0)) -> https://reurl.cc/rKo52Z | I3: =IF(B3="","",_xlfn.XLOOKUP(B3,'2.專案函文紀錄'!K:K,'2.專案函文紀錄'!Q:Q,"查無此案紀錄",0)) -> Z:\03.專案管控專區\桃園市政府\桃園市政府工務局\2025\115年桃園市興辦公共設施用地取得專業服務\04.專案工作事項\01.派工案件管控\1.各派工案辦理紀錄\115年_派工單號001\ | J3: {=_xlfn.TEXTJOIN("、", TRUE, _xlfn._xlws.FILTER(IF('2.專案函文紀錄'!$D$2:$D$99="", "", '2.專案函文紀錄'!$D$2:$D$99 & "_" & '2.專案函文紀錄'!$E$2:$E$99), ('2.專案函文紀錄'!$H$2:$H$99 = C3) * ('2.專案函文紀錄'!$B$2:$B$99 = "桃園市政府工務局") * ('2.專案函文紀錄'!$D$2:$D$99 <> "查無此案紀錄"), ""))} -> 115年01月05日_桃工用字第1150000279號 | K3: {=_xlfn.TEXTJOIN(CHAR(10), TRUE, _xlfn._xlws.FILTER(IF('2.專案函文紀錄'!$D$2:$D$99="", "", '2.專案函文紀錄'!$D$2:$D$99 & "_" & '2.專案函文紀錄'!$E$2:$E$99 & "_" & '2.專案函文紀錄'!$G$2:$G$99), ('2.專案函文紀錄'!$H$2:$H$99 = C3) * ('2.專案函文紀錄'!$B$2:$B$99 = "桃園市政府工務局") * ('2.專案函文紀錄'!$D$2:$D$99 <> "查無此案紀錄"), ""))} -> 115年01月05日_桃工用字第1150000279號_通知辦理115年_派工單號001 | L3: {=_xlfn.TEXTJOIN("、", TRUE, _xlfn._xlws.FILTER(IF('2.專案函文紀錄'!$D$2:$D$99="", "", '2.專案函文紀錄'!$D$2:$D$99 & "_" & '2.專案函文紀錄'!$E$2:$E$99), ('2.專案函文紀錄'!$H$2:$H$99 = D3) * ('2.專案函文紀錄'!$B$2:$B$99 = "乾坤測繪科技有限公司") * ('2.專案函文紀錄'!$D$2:$D$99 <> "查無此案紀錄"), ""))} | M3: {=_xlfn.TEXTJOIN(CHAR(10), TRUE, _xlfn._xlws.FILTER(IF('2.專案函文紀錄'!$D$2:$D$99="", "", '2.專案函文紀錄'!$D$2:$D$99 & "_" & '2.專案函文紀錄'!$E$2:$E$99 & "_" & '2.專案函文紀錄'!$G$2:$G$99), ('2.專案函文紀錄'!$H$2:$H$99 = D3) * ('2.專案函文紀錄'!$B$2:$B$99 = "乾坤測繪科技有限公司") * ('2.專案函文紀錄'!$D$2:$D$99 <> "查無此案紀錄"), ""))} | N3: =IF($D3="01地上物查估作業",#REF!, "") | P3: =IF($D3="02.土地協議市價查估作業",#REF!, "") | R3: =IF($D3="03.土地徵收市價查估作業",#REF!, "") | T3: =IF($D3="04.相關計畫書製作",#REF!, "") | V3: =IF($D3="05.測量作業",#REF!, "") | X3: =IF($D3="06.樁位測釘作業",#REF!, "") | AB3: =SUM(O3,Q3,S3,U3,W3,Y3,AA3) -> 0 | AC3: =AB3 -> 0 | AD3: =6035000-AC3 -> 6035000
A4: 2 | B4: 115年_派工單號002 | C4: =IF(B4="","",_xlfn.XLOOKUP(B4,'2.專案函文紀錄'!K:K,'2.專案函文紀錄'!H:H,"查無此案紀錄",0)) -> 桃園市八德區霄裡公園及周邊道路興闢工程 | D4: =IF(B4="","",_xlfn.XLOOKUP(B4,'2.專案函文紀錄'!K:K,'2.專案函文紀錄'!I:I,"查無此案紀錄",0)) -> 02.土地協議市價查估作業 | E4: =IF(B4="","",_xlfn.XLOOKUP(B4,'2.專案函文紀錄'!K:K,'2.專案函文紀錄'!J:J,"查無此案紀錄",0)) -> 桃園市八德區霄裡公園及周邊道路興闢工程_02.土地協議市價查估作業 | F4: =IF(B4="","",_xlfn.XLOOKUP(B4,'2.專案函文紀錄'!K:K,'2.專案函文紀錄'!N:N,"查無此案紀錄",0)) -> 行政助理 粘亞溱 | G4: =IF(B4="","",_xlfn.XLOOKUP(B4,'2.專案函文紀錄'!K:K,'2.專案函文紀錄'!O:O,"查無此案紀錄",0)) -> 昇揚估價師 欒中文 | H4: =IF(B4="","",_xlfn.XLOOKUP(B4,'2.專案函文紀錄'!K:K,'2.專案函文紀錄'!P:P,"查無此案紀錄",0)) -> https://reurl.cc/EbM8Dm | I4: =IF(B4="","",_xlfn.XLOOKUP(B4,'2.專案函文紀錄'!K:K,'2.專案函文紀錄'!Q:Q,"查無此案紀錄",0)) -> Z:\03.專案管控專區\桃園市政府\桃園市政府工務局\2025\115年桃園市興辦公共設施用地取得專業服務\04.專案工作事項\01.派工案件管控\1.各派工案辦理紀錄\115年_派工單號002\ | J4: {=_xlfn.TEXTJOIN("、", TRUE, _xlfn._xlws.FILTER(IF('2.專案函文紀錄'!$D$2:$D$99="", "", '2.專案函文紀錄'!$D$2:$D$99 & "_" & '2.專案函文紀錄'!$E$2:$E$99), ('2.專案函文紀錄'!$H$2:$H$99 = C4) * ('2.專案函文紀錄'!$B$2:$B$99 = "桃園市政府工務局") * ('2.專案函文紀錄'!$D$2:$D$99 <> "查無此案紀錄"), ""))} -> 115年01月15日_桃工用字第1150001582號 | K4: {=_xlfn.TEXTJOIN(CHAR(10), TRUE, _xlfn._xlws.FILTER(IF('2.專案函文紀錄'!$D$2:$D$99="", "", '2.專案函文紀錄'!$D$2:$D$99 & "_" & '2.專案函文紀錄'!$E$2:$E$99 & "_" & '2.專案函文紀錄'!$G$2:$G$99), ('2.專案函文紀錄'!$H$2:$H$99 = C4) * ('2.專案函文紀錄'!$B$2:$B$99 = "桃園市政府工務局") * ('2.專案函文紀錄'!$D$2:$D$99 <> "查無此案紀錄"), ""))} -> 115年01月15日_桃工用字第1150001582號_通知辦理115年_派工單號002 | L4: {=_xlfn.TEXTJOIN("、", TRUE, _xlfn._xlws.FILTER(IF('2.專案函文紀錄'!$D$2:$D$99="", "", '2.專案函文紀錄'!$D$2:$D$99 & "_" & '2.專案函文紀錄'!$E$2:$E$99), ('2.專案函文紀錄'!$H$2:$H$99 = D4) * ('2.專案函文紀錄'!$B$2:$B$99 = "乾坤測繪科技有限公司") * ('2.專案函文紀錄'!$D$2:$D$99 <> "查無此案紀錄"), ""))} | M4: {=_xlfn.TEXTJOIN(CHAR(10), TRUE, _xlfn._xlws.FILTER(IF('2.專案函文紀錄'!$D$2:$D$99="", "", '2.專案函文紀錄'!$D$2:$D$99 & "_" & '2.專案函文紀錄'!$E$2:$E$99 & "_" & '2.專案函文紀錄'!$G$2:$G$99), ('2.專案函文紀錄'!$H$2:$H$99 = D4) * ('2.專案函文紀錄'!$B$2:$B$99 = "乾坤測繪科技有限公司") * ('2.專案函文紀錄'!$D$2:$D$99 <> "查無此案紀錄"), ""))} | N4: =IF($D4="01地上物查估作業",#REF!, "") | P4: =IF($D4="02.土地協議市價查估作業",#REF!, "") -> #REF! | R4: =IF($D4="03.土地徵收市價查估作業",#REF!, "") | T4: =IF($D4="04.相關計畫書製作",#REF!, "") | V4: =IF($D4="05.測量作業",#REF!, "") | X4: =IF($D4="06.樁位測釘作業",#REF!, "") | Z4: =IF($D4="07.辦理教育訓練",#REF!, "")
A5: 3 | B5: 115年_派工單號003 | C5: =IF(B5="","",_xlfn.XLOOKUP(B5,'2.專案函文紀錄'!K:K,'2.專案函文紀錄'!H:H,"查無此案紀錄",0)) -> 中壢區龍岡路4-1-10M計畫道路路口瓶頸打通工程 | D5: =IF(B5="","",_xlfn.XLOOKUP(B5,'2.專案函文紀錄'!K:K,'2.專案函文紀錄'!I:I,"查無此案紀錄",0)) -> 02.土地協議市價查估作業 | E5: =IF(B5="","",_xlfn.XLOOKUP(B5,'2.專案函文紀錄'!K:K,'2.專案函文紀錄'!J:J,"查無此案紀錄",0)) -> 中壢區龍岡路4-1-10M計畫道路路口瓶頸打通工程_02.土地協議市價查估作業 | F5: =IF(B5="","",_xlfn.XLOOKUP(B5,'2.專案函文紀錄'!K:K,'2.專案函文紀錄'!N:N,"查無此案紀錄",0)) -> 約催助理 吳佳芸 | G5: =IF(B5="","",_xlfn.XLOOKUP(B5,'2.專案函文紀錄'!K:K,'2.專案函文紀錄'!O:O,"查無此案紀錄",0)) -> 全國估價師 張子亮 | H5: =IF(B5="","",_xlfn.XLOOKUP(B5,'2.專案函文紀錄'!K:K,'2.專案函文紀錄'!P:P,"查無此案紀錄",0)) -> https://reurl.cc/rKjOr1 | I5: =IF(B5="","",_xlfn.XLOOKUP(B5,'2.專案函文紀錄'!K:K,'2.專案函文紀錄'!Q:Q,"查無此案紀錄",0)) -> Z:\03.專案管控專區\桃園市政府\桃園市政府工務局\2025\115年桃園市興辦公共設施用地取得專業服務\04.專案工作事項\01.派工案件管控\1.各派工案辦理紀錄\115年_派工單號003\ | J5: {=_xlfn.TEXTJOIN("、", TRUE, _xlfn._xlws.FILTER(IF('2.專案函文紀錄'!$D$2:$D$99="", "", '2.專案函文紀錄'!$D$2:$D$99 & "_" & '2.專案函文紀錄'!$E$2:$E$99), ('2.專案函文紀錄'!$H$2:$H$99 = C5) * ('2.專案函文紀錄'!$B$2:$B$99 = "桃園市政府工務局") * ('2.專案函文紀錄'!$D$2:$D$99 <> "查無此案紀錄"), ""))} -> 115年01月14日_桃工用字第1150002112號 | K5: {=_xlfn.TEXTJOIN(CHAR(10), TRUE, _xlfn._xlws.FILTER(IF('2.專案函文紀錄'!$D$2:$D$99="", "", '2.專案函文紀錄'!$D$2:$D$99 & "_" & '2.專案函文紀錄'!$E$2:$E$99 & "_" & '2.專案函文紀錄'!$G$2:$G$99), ('2.專案函文紀錄'!$H$2:$H$99 = C5) * ('2.專案函文紀錄'!$B$2:$B$99 = "桃園市政府工務局") * ('2.專案函文紀錄'!$D$2:$D$99 <> "查無此案紀錄"), ""))} -> 115年01月14日_桃工用字第1150002112號_通知辦理115年_派工單號003 | N5: =IF($D5="01地上物查估作業",#REF!, "") | P5: =IF($D5="02.土地協議市價查估作業",#REF!, "") -> #REF! | R5: =IF($D5="03.土地徵收市價查估作業",#REF!, "") | T5: =IF($D5="04.相關計畫書製作",#REF!, "") | V5: =IF($D5="05.測量作業",#REF!, "") | X5: =IF($D5="06.樁位測釘作業",#REF!, "") | Z5: =IF($D5="07.辦理教育訓練",#REF!, "")
A6: 4 | C6: =IF(B6="","",_xlfn.XLOOKUP(B6,#REF!,#REF!,"查無此案名(工程名稱)", 0)) | E6: =IF(B6="","",_xlfn.XLOOKUP(B6,'2.專案函文紀錄'!K:K,'2.專案函文紀錄'!G:G,"查無此案紀錄",0)) | G6: =IF(B6="","",_xlfn.XLOOKUP(B6,#REF!,#REF!,"查無此紀錄",0)) | H6: =IF(B6="","",_xlfn.XLOOKUP(B6,'2.專案函文紀錄'!K:K,'2.專案函文紀錄'!P:P,"查無此案紀錄",0)) | N6: =IF($D6="01地上物查估作業",#REF!, "") | P6: =IF($D6="02.土地協議市價查估作業",#REF!, "") | R6: =IF($D6="03.土地徵收市價查估作業",#REF!, "") | T6: =IF($D6="04.相關計畫書製作",#REF!, "") | V6: =IF($D6="05.測量作業",#REF!, "") | X6: =IF($D6="06.樁位測釘作業",#REF!, "") | Z6: =IF($D6="07.辦理教育訓練",#REF!, "")
A7: 5 | C7: =IF(B7="","",_xlfn.XLOOKUP(B7,#REF!,#REF!,"查無此案名(工程名稱)", 0)) | E7: =IF(B7="","",_xlfn.XLOOKUP(B7,'2.專案函文紀錄'!K:K,'2.專案函文紀錄'!G:G,"查無此案紀錄",0)) | G7: =IF(B7="","",_xlfn.XLOOKUP(B7,#REF!,#REF!,"查無此紀錄",0)) | H7: =IF(B7="","",_xlfn.XLOOKUP(B7,'2.專案函文紀錄'!K:K,'2.專案函文紀錄'!P:P,"查無此案紀錄",0)) | N7: =IF($D7="01地上物查估作業",#REF!, "") | P7: =IF($D7="02.土地協議市價查估作業",#REF!, "") | R7: =IF($D7="03.土地徵收市價查估作業",#REF!, "") | T7: =IF($D7="04.相關計畫書製作",#REF!, "") | V7: =IF($D7="05.測量作業",#REF!, "") | X7: =IF($D7="06.樁位測釘作業",#REF!, "") | Z7: =IF($D7="07.辦理教育訓練",#REF!, "")
A8: 6 | C8: =IF(B8="","",_xlfn.XLOOKUP(B8,#REF!,#REF!,"查無此案名(工程名稱)", 0)) | E8: =IF(B8="","",_xlfn.XLOOKUP(B8,'2.專案函文紀錄'!K:K,'2.專案函文紀錄'!G:G,"查無此案紀錄",0)) | G8: =IF(B8="","",_xlfn.XLOOKUP(B8,#REF!,#REF!,"查無此紀錄",0)) | H8: =IF(B8="","",_xlfn.XLOOKUP(B8,'2.專案函文紀錄'!K:K,'2.專案函文紀錄'!P:P,"查無此案紀錄",0)) | N8: =IF($D8="01地上物查估作業",#REF!, "") | P8: =IF($D8="02.土地協議市價查估作業",#REF!, "") | R8: =IF($D8="03.土地徵收市價查估作業",#REF!, "") | T8: =IF($D8="04.相關計畫書製作",#REF!, "") | V8: =IF($D8="05.測量作業",#REF!, "") | X8: =IF($D8="06.樁位測釘作業",#REF!, "") | Z8: =IF($D8="07.辦理教育訓練",#REF!, "")
A9: 7 | C9: =IF(B9="","",_xlfn.XLOOKUP(B9,#REF!,#REF!,"查無此案名(工程名稱)", 0)) | E9: =IF(B9="","",_xlfn.XLOOKUP(B9,'2.專案函文紀錄'!K:K,'2.專案函文紀錄'!G:G,"查無此案紀錄",0)) | G9: =IF(B9="","",_xlfn.XLOOKUP(B9,#REF!,#REF!,"查無此紀錄",0)) | H9: =IF(B9="","",_xlfn.XLOOKUP(B9,'2.專案函文紀錄'!K:K,'2.專案函文紀錄'!P:P,"查無此案紀錄",0)) | N9: =IF($D9="01地上物查估作業",#REF!, "") | P9: =IF($D9="02.土地協議市價查估作業",#REF!, "") | R9: =IF($D9="03.土地徵收市價查估作業",#REF!, "") | T9: =IF($D9="04.相關計畫書製作",#REF!, "") | V9: =IF($D9="05.測量作業",#REF!, "") | X9: =IF($D9="06.樁位測釘作業",#REF!, "") | Z9: =IF($D9="07.辦理教育訓練",#REF!, "")
A10: 8 | E10: =IF(B10="","",_xlfn.XLOOKUP(B10,'2.專案函文紀錄'!K:K,'2.專案函文紀錄'!G:G,"查無此案紀錄",0)) | G10: =IF(B10="","",_xlfn.XLOOKUP(B10,#REF!,#REF!,"查無此紀錄",0)) | H10: =IF(B10="","",_xlfn.XLOOKUP(B10,'2.專案函文紀錄'!K:K,'2.專案函文紀錄'!P:P,"查無此案紀錄",0)) | N10: =IF($D10="01地上物查估作業",#REF!, "") | P10: =IF($D10="02.土地協議市價查估作業",#REF!, "") | R10: =IF($D10="03.土地徵收市價查估作業",#REF!, "") | T10: =IF($D10="04.相關計畫書製作",#REF!, "") | V10: =IF($D10="05.測量作業",#REF!, "") | X10: =IF($D10="06.樁位測釘作業",#REF!, "") | Z10: =IF($D10="07.辦理教育訓練",#REF!, "")
A11: 9
A12: 10
A13: 11
A14: 12
A15: 13
A16: 14
A17: 15
A18: 16
A19: 17
A20: 18
A21: 19
A22: 20
... A44: 42
T233: 派0工單04

Sheet 欄位檢核
A1: 作業類別
A2: #.專案行政作業
A3: 00.專案會議
A4: 01.地上物查估作業
A5: 02.土地協議市價查估作業
A6: 03.土地徵收市價查估作業
A7: 04.相關計畫書製作
A8: 05.測量作業
A9: 06.樁位測釘作業
A10: 07.辦理教育訓練
A11: 08.作業提繳事項

Sheet 新建工程處工程清單
A1: 上版日期 | B1: 主題 | C1: 發布單位
A2: 114-10-21 | B2: 機場捷運A7站區開發案區外道路（T字型聯外道路–變一）新闢工程 | C2: 新建工程處
A3: 114-06-24 | B3: 機場捷運A7站區開發案區外道路(變二)新闢工程 | C3: 新建工程處
A4: 114-01-20 | B4: 桃園市龜山區文化一路至青山路道路新闢工程 | C4: 新建工程處
A5: 113-07-02 | B5: 桃園市八德區永豐路截彎取直工程暨八德區茄苳國小通學步道及生態綠廊建置工程 | C5: 新建工程處
A6: 113-06-11 | B6: 桃42線月桃路道路拓寬工程 | C6: 新建工程處
A7: 113-01-11 | B7: 八德區山下街打通至新興路道路新闢工程 | C7: 新建工程處
A8: 113-01-10 | B8: 桃園市中壢區吉林路道路拓寬工程(文中路二段-松江南路) | C8: 新建工程處
A9: 113-01-03 | B9: 龍慈路延伸至台66線道路新闢工程(都外段) | C9: 新建工程處
